Workbook

Sheet README
B2: MYNT (GCASH) VALUATION MODEL — corrected build
B4: WHAT THIS IS
B5: A live-formula valuation model. Change any BLUE cell on Assumptions and every dependent figure recalculates.
B6: BLUE = input you may edit. BLACK = formula. GREEN = link to another sheet. YELLOW fill = the levers that move the answer most.
B8: WHAT WAS FIXED IN THIS BUILD
B9: 1. Broken sheet references. 18 formula errors came from unquoted sheet names containing a hyphen or space, which Excel read as external-workbook links (=DCF-[1]FCFF!B21). All now quoted: ='DCF-FCFF'!B21.
B10: 2. No discounting. 'Sum PV FCFF' summed the RAW forecast cash flows. Nothing was discounted, and a lone PV cell sat orphaned. Both DCFs now discount every year explicitly.
B11: 3. Terminal value was zero. Both DCFs pointed at Forecast!G9 and Forecast!G12; the sheet ended at column F, so the terminal cash flow was an empty cell.
B12: 4. Forecast growth was off by one. 2027 used the 2028 rate, 2028 used 2029, 2029 used 2030, and 2030 referenced an empty cell, so it grew at zero.
B13: 5. EV/EBITDA per share was negative. (EBITDA + debt - free cash) / shares mixes a flow with two stocks and returned -0.0149, making every EV comp negative. Rebuilt as EV = multiple x EBITDA, then equity = EV - debt + cash.
B14: 6. The WACC sanity check tested the wrong cell. 'Check: g < rf' compared the equity weight against the risk-free rate, so it always read FAIL.
B15: 7. Sensitivity was dead. 74 hardcoded cells, zero formulas. Both grids are now live and recalculate.
... B23: CAPM for the cost of equity; WACC for the cost of capital; a five-year explicit forecast; FCFF discounted at WACC and FCFE at the cost of equity; Gordon Growth terminal value; justified P/B and P/E from fundamentals; peer comparables; scenario and sensitivity analysis.

Sheet Assumptions
A1: ASSUMPTIONS — every input in one place
A2: Blue cells are editable. Yellow fill marks the levers that move the answer most.
A4: Input | B4: Value | C4: Units | D4: Source
A5: DISCOUNT RATE
A6: Risk-free rate | B6: 0.0726 | C6: % | D6: PH 10Y government bond yield, 14 Jul 2026 (Trading Economics)
A7: Equity risk premium | B7: 0.067 | C7: % | D7: Damodaran, Philippines
A8: Beta | B8: 1.6 | C8: x | D8: Midpoint of Sea, PayPal, Adyen. Mynt has never traded.
A9: Cost of equity Ke = rf + beta x ERP | B9: =$B$6+$B$8*$B$7 | C9: %
A10: After-tax cost of debt | B10: 0.0431 | C10: % | D10: Bank loans 5.0-6.5%, tax-effected
A11: Debt weight (market) | B11: 0.03 | C11: % | D11: At the offer price
A12: Equity weight (market) | B12: =1-$B$11
A13: WACC | B13: =$B$11*$B$10+$B$12*$B$9
A14: Terminal growth g | B14: 0.045 | C14: % | D14: Below Philippine inflation. Must stay below the risk-free rate.
A15: Tax rate | B15: 0.25 | C15: % | D15: CREATE Act corporate income tax
A16: Check: is g below the risk-free rate? | B16: =IF($B$14<$B$6,"OK","VIOLATION") | D16: Was comparing the equity weight against rf, so it always read FAIL.
A18: REVENUE GROWTH PATH
A19: Growth FY2026E | B19: 0.15 | C19: % | D19: Anchored on Q1-2026 actual 14.8%
A20: Growth FY2027E | B20: 0.13 | C20: % | D20: Declining gradually
A21: Growth FY2028E | B21: 0.11 | C21: % | D21: Declining gradually
A22: Growth FY2029E | B22: 0.09 | C22: % | D22: Declining gradually
A23: Growth FY2030E | B23: 0.075 | C23: % | D23: Declining gradually
A25: OPERATING RATIOS
A26: EBIT margin | B26: 0.248 | C26: % | D26: FY2025 actual, held flat
A27: D&A as % of revenue | B27: 0.0087774019 | C27: % | D27: FY2025 actual
A28: Capex as % of revenue | B28: 0.0057323602 | C28: % | D28: FY2025 actual
A29: Loan book as % of revenue | B29: 0.517937 | C29: % | D29: FY2025: net loans / adjusted revenue
A30: Debt-funded share of loan book | B30: 0.42527176 | C30: % | D30: Total debt / net loans at Q1-2026
A31: Net margin | B31: 0.21649795 | C31: % | D31: FY2025 actual. Used when the net-income basis below is set to 2.
A32: Net income basis 1 = NOPAT 2 = net margin x revenue | B32: 2 | D32: The published model.py derives net income as net margin x revenue, but the workbook used NOPAT. The two differ by roughly PHP 2.7bn a year. Basis 2 reproduces the published figure; basis 1 is the workbook as originally built.
A34: CASH AND THE FREE-CASH SWITCH
A35: Cash and equivalents | B35: 67758.1 | C35: PHP M | D35: Prospectus printed p. 35
A36: Float liabilities | B36: 99612 | C36: PHP M | D36: Prospectus printed p. 35
A37: Cash in trust | B37: 74032.2 | C37: PHP M | D37: Prospectus printed p. 35
A38: Corporate cash, disclosed | B38: 39210.8 | C38: PHP M | D38: Prospectus printed p. 35, corporate cash at 31 Mar 2026
A39: Free cash (memo: inferred basis) | B39: =$B$35-($B$36-$B$37) | C39: PHP M | D39: superseded by the disclosed line above
A40: Free-cash share | B40: 1 | C40: % | D40: 0-100%. How much of the balance is genuinely distributable. Prospectus p.44 states wallet funds are held in liquid assets and cannot fund lending.
A41: Free-cash adjustment | B41: =$B$38*$B$40
A43: OFFER AND BALANCE SHEET
A44: Offer price | B44: 10 | C44: PHP | D44: Prospectus printed p. i
A45: Shares outstanding, post-offer | B45: 66895.913 | C45: M | D45: Prospectus printed p. 89
...

Sheet Historicals
A1: HISTORICALS — as reported
A2: Audited by Isla Lipana & Co. under PFRS. PHP millions.
A4: PHP millions | B4: FY2023 | C4: FY2024 | D4: FY2025 | F4: Prospectus, printed page
A5: Adjusted Revenues | B5: 33602.1 | C5: 54127.8 | D5: 79670.5 | F5: p. 112
A6: EBITDA | B6: 6346 | C6: 13462.1 | D6: 20429 | F6: p. 37
A7: Operating profit | B7: 6072.3 | C7: 13040.2 | D7: 19729.7 | F7: p. 34
A8: Net income | B8: 6383.2 | C8: 11127.9 | D8: 17248.5 | F8: p. 34
A9: Net loan receivables | B9: 11947.6 | C9: 34141.7 | D9: 41264.3 | F9: p. 35
A10: Total debt | B10: 0 | C10: 19000 | D10: 19100.3 | F10: p. 35
A11: D&A | B11: 273.8 | C11: 421.8 | D11: 699.3 | F11: p. 37
A12: Capital expenditure | B12: 298.1 | C12: 520.7 | D12: 456.7 | F12: p. 142
A14: Note: the FY2023 loan figure is the NET receivable (11,872.4 + 75.2). An earlier table used the GROSS on-book figure of 14,273.8 for 2023 while the other years were net, which mixed two definitions in one series.

Sheet Unit Economics
A1: UNIT ECONOMICS — derived from Historicals
A2: Every cell is a formula pointing at Historicals. Nothing retyped.
A4: Net margin FY2025 | B4: =Historicals!D8/Historicals!D5
A5: EBITDA margin FY2025 | B5: =Historicals!D6/Historicals!D5
A6: Operating margin FY2025 | B6: =Historicals!D7/Historicals!D5 | D6: Feeds the EBIT margin assumption
A7: Loan book / revenue FY2025 | B7: =Historicals!D9/Historicals!D5
A8: D&A / revenue FY2025 | B8: =Historicals!D11/Historicals!D5
A9: Capex / revenue FY2025 | B9: =Historicals!D12/Historicals!D5 | D9: Under 1% in every period
A10: Debt-funded share of the loan book | B10: =Assumptions!$B$46/Assumptions!$B$55 | D10: Total debt over NET loans at Q1-2026. On GROSS on-book loans of 56,162.5 the same ratio is 36.9%.

Sheet Forecast
A1: FORECAST — FY2026E to FY2030E
A2: Growth rates now step correctly year by year. The previous build used the 2028 rate for 2027, the 2029 rate for 2028, and an empty cell for 2030.
A4: PHP millions | B4: FY2026E | C4: FY2027E | D4: FY2028E | E4: FY2029E | F4: FY2030E | H4: Build
A5: Revenue | B5: =Assumptions!$B$51*(1+Assumptions!$B$19) | C5: =B5*(1+Assumptions!$B$20) | D5: =C5*(1+Assumptions!$B$21) | E5: =D5*(1+Assumptions!$B$22) | F5: =E5*(1+Assumptions!$B$23) | H5: prior year x (1 + that year's growth rate)
A6: growth | B6: =Assumptions!$B$19 | C6: =Assumptions!$B$20 | D6: =Assumptions!$B$21 | E6: =Assumptions!$B$22 | F6: =Assumptions!$B$23
A7: EBIT | B7: =B5*Assumptions!$B$26 | C7: =C5*Assumptions!$B$26 | D7: =D5*Assumptions!$B$26 | E7: =E5*Assumptions!$B$26 | F7: =F5*Assumptions!$B$26 | H7: revenue x EBIT margin
A8: Less: tax | B8: =-B7*Assumptions!$B$15 | C8: =-C7*Assumptions!$B$15 | D8: =-D7*Assumptions!$B$15 | E8: =-E7*Assumptions!$B$15 | F8: =-F7*Assumptions!$B$15
A9: NOPAT | B9: =B7+B8 | C9: =C7+C8 | D9: =D7+D8 | E9: =E7+E8 | F9: =F7+F8
A10: Add: D&A | B10: =B5*Assumptions!$B$27 | C10: =C5*Assumptions!$B$27 | D10: =D5*Assumptions!$B$27 | E10: =E5*Assumptions!$B$27 | F10: =F5*Assumptions!$B$27
A11: Less: capex | B11: =-B5*Assumptions!$B$28 | C11: =-C5*Assumptions!$B$28 | D11: =-D5*Assumptions!$B$28 | E11: =-E5*Assumptions!$B$28 | F11: =-F5*Assumptions!$B$28
A12: Loan book, closing | B12: =B5*Assumptions!$B$29 | C12: =C5*Assumptions!$B$29 | D12: =D5*Assumptions!$B$29 | E12: =E5*Assumptions!$B$29 | F12: =F5*Assumptions!$B$29 | H12: revenue x loan-to-revenue ratio
A13: Loan book, closing (floored at Q1-2026 actual) | B13: =MAX(B12,Assumptions!$B$55) | C13: =C12 | D13: =D12 | E13: =E12 | F13: =F12 | H13: FY2026 cannot close below the 31 Mar 2026 reported balance
A14: Less: increase in loan book | B14: =-(B13-Assumptions!$B$54) | C14: =-(C13-B13) | D14: =-(D13-C13) | E14: =-(E13-D13) | F14: =-(F13-E13) | H14: FY2026 measured against the FY2025 closing book (period-matched)
A15: FREE CASH FLOW TO FIRM | B15: =B9+B10+B11+B14 | C15: =C9+C10+C11+C14 | D15: =D9+D10+D11+D14 | E15: =E9+E10+E11+E14 | F15: =F9+F10+F11+F14
A17: Net income | B17: =IF(Assumptions!$B$32=2,B5*Assumptions!$B$31,B9) | C17: =IF(Assumptions!$B$32=2,C5*Assumptions!$B$31,C9) | D17: =IF(Assumptions!$B$32=2,D5*Assumptions!$B$31,D9) | E17: =IF(Assumptions!$B$32=2,E5*Assumptions!$B$31,E9) | F17: =IF(Assumptions!$B$32=2,F5*Assumptions!$B$31,F9) | H17: basis 1 = NOPAT; basis 2 = revenue x net margin (the published basis)
A18: Add: new debt on loan growth | B18: =-B14*Assumptions!$B$30 | C18: =-C14*Assumptions!$B$30 | D18: =-D14*Assumptions!$B$30 | E18: =-E14*Assumptions!$B$30 | F18: =-F14*Assumptions!$B$30 | H18: the debt-funded share of the increase
A19: FREE CASH FLOW TO EQUITY | B19: =B17+B10+B11+B14+B18 | C19: =C17+C10+C11+C14+C18 | D19: =D17+D10+D11+D14+D18 | E19: =E17+E10+E11+E14+E18 | F19: =F17+F10+F11+F14+F18

Sheet WACC
A1: COST OF CAPITAL
A3: Risk-free rate | B3: =Assumptions!$B$6 | D3: PH 10Y, 14 Jul 2026
A4: Beta | B4: =Assumptions!$B$8 | D4: Peer midpoint. Mynt has never traded.
A5: Equity risk premium | B5: =Assumptions!$B$7 | D5: Damodaran, Philippines
A6: Cost of equity Ke | B6: =Assumptions!$B$9 | D6: rf + beta x ERP
A7: After-tax cost of debt | B7: =Assumptions!$B$10
A8: Debt weight | B8: =Assumptions!$B$11 | D8: At the offer price
A9: Equity weight | B9: =Assumptions!$B$12
A10: WACC | B10: =Assumptions!$B$13 | D10: Wd x Kd + We x Ke
A11: Terminal growth g | B11: =Assumptions!$B$14
A13: Check: is g below the risk-free rate? | B13: =IF(Assumptions!$B$14<Assumptions!$B$6,"OK","VIOLATION") | D13: Previously compared the EQUITY WEIGHT against rf, so it always read FAIL. A perpetual growth rate above the risk-free rate implies the company eventually becomes the whole economy.

Sheet DCF-FCFF
A1: DISCOUNTED CASH FLOW — FREE CASH FLOW TO THE FIRM
A2: Discounted at WACC, then less debt and plus the free-cash adjustment. One column per forecast year.
A4: PHP millions | B4: FY2026E | C4: FY2027E | D4: FY2028E | E4: FY2029E | F4: FY2030E | G4: Terminal | I4: Build
A5: Free cash flow | B5: =Forecast!B15 | C5: =Forecast!C15 | D5: =Forecast!D15 | E5: =Forecast!E15 | F5: =Forecast!F15 | G5: =F5*(1+Assumptions!$B$14) | I5: final year grown one period at g
A6: Discount period t | B6: 1 | C6: 2 | D6: 3 | E6: 4 | F6: 5 | G6: 5 | I6: terminal value discounted at t = 5
A7: Discount factor at WACC | B7: =1/(1+Assumptions!$B$13)^B6 | C7: =1/(1+Assumptions!$B$13)^C6 | D7: =1/(1+Assumptions!$B$13)^D6 | E7: =1/(1+Assumptions!$B$13)^E6 | F7: =1/(1+Assumptions!$B$13)^F6 | G7: =1/(1+Assumptions!$B$13)^G6
A8: Terminal value | G8: =G5/(Assumptions!$B$13-Assumptions!$B$14) | I8: Gordon Growth on the terminal cash flow
A9: Present value | B9: =B5*B7 | C9: =C5*C7 | D9: =D5*D7 | E9: =E5*E7 | F9: =F5*F7 | G9: =G8*G7
A11: PV of FY2026E–FY2030E | B11: =SUM(B9:F9) | I11: sum of the discounted years above
A12: PV of terminal value | B12: =G9
A13: Total present value | B13: =B11+B12 | C13: =B12/B13 | I13: column C: terminal value as a share of the total
A14: Less: total debt | B14: =-Assumptions!$B$46
A15: Plus: free-cash adjustment | B15: =Assumptions!$B$41 | I15: scaled by the free-cash share on Assumptions
A16: Equity value | B16: =B13+B14+B15
A17: Shares outstanding (M) | B17: =Assumptions!$B$45
A18: VALUE PER SHARE (PHP) | B18: =B16/B17
A20: Offer price | B20: =Assumptions!$B$44
A21: Offer as a multiple of this value | B21: =Assumptions!$B$44/B18

Sheet DCF-FCFE
A1: DISCOUNTED CASH FLOW — FREE CASH FLOW TO EQUITY (primary)
A2: Discounted at the cost of equity. No debt or cash bridge is needed: the flow is already the equity holder's.
A4: PHP millions | B4: FY2026E | C4: FY2027E | D4: FY2028E | E4: FY2029E | F4: FY2030E | G4: Terminal | I4: Build
A5: Free cash flow | B5: =Forecast!B19 | C5: =Forecast!C19 | D5: =Forecast!D19 | E5: =Forecast!E19 | F5: =Forecast!F19 | G5: =F5*(1+Assumptions!$B$14) | I5: final year grown one period at g
A6: Discount period t | B6: 1 | C6: 2 | D6: 3 | E6: 4 | F6: 5 | G6: 5 | I6: terminal value discounted at t = 5
A7: Discount factor at Ke | B7: =1/(1+Assumptions!$B$9)^B6 | C7: =1/(1+Assumptions!$B$9)^C6 | D7: =1/(1+Assumptions!$B$9)^D6 | E7: =1/(1+Assumptions!$B$9)^E6 | F7: =1/(1+Assumptions!$B$9)^F6 | G7: =1/(1+Assumptions!$B$9)^G6
A8: Terminal value | G8: =G5/(Assumptions!$B$9-Assumptions!$B$14) | I8: Gordon Growth on the terminal cash flow
A9: Present value | B9: =B5*B7 | C9: =C5*C7 | D9: =D5*D7 | E9: =E5*E7 | F9: =F5*F7 | G9: =G8*G7
A11: PV of FY2026E–FY2030E | B11: =SUM(B9:F9) | I11: sum of the discounted years above
A12: PV of terminal value | B12: =G9
A13: Total present value | B13: =B11+B12 | C13: =B12/B13 | I13: column C: terminal value as a share of the total
A14: Shares outstanding (M) | B14: =Assumptions!$B$45
A15: VALUE PER SHARE (PHP) | B15: =B13/B14
A17: Offer price | B17: =Assumptions!$B$44
A18: Offer as a multiple of this value | B18: =Assumptions!$B$44/B15

Sheet Justified Multiples
A1: JUSTIFIED MULTIPLES — the Gordon model rearranged
A2: Uses no forecast at all. Only ROE, growth and the cost of equity.
A4: ROE on average equity | B4: =Assumptions!$B$56 | D4: Prospectus p.36
A5: ROE on ending equity | B5: =Assumptions!$B$57 | D5: Computed
A6: Cost of equity Ke | B6: =Assumptions!$B$9
A7: Terminal growth g | B7: =Assumptions!$B$14
A8: Justified P/B (ROE-g)/(Ke-g), avg equity | B8: =(B4-B7)/(B6-B7)
A9: Justified P/B, ending equity | B9: =(B5-B7)/(B6-B7)
A10: Book equity per share | B10: =Assumptions!$B$47/Assumptions!$B$45
A11: Implied value, high (PHP) | B11: =B8*B10
A12: Implied value, low (PHP) | B12: =B9*B10
A14: WHAT THE OFFER PRICE DEMANDS
A15: Offer P/B on adjusted tangible book | B15: =Assumptions!$B$44/Assumptions!$B$48 | D15: PHP 1.04 per share, prospectus p.89
A16: Required ROE = g + P/B x (Ke - g) | B16: =Assumptions!$B$14+(Assumptions!$B$44/Assumptions!$B$48)*(Assumptions!$B$9-Assumptions!$B$14) | D16: Against the 32.1% actually earned in FY2025

Sheet Comps
A1: PEER COMPARABLES — cross-check only
A2: The EV/EBITDA bridge was rebuilt. It previously divided (EBITDA + debt - cash) by shares, mixing a flow with two stocks, and returned a NEGATIVE per-share figure.
A4: Peer | B4: P/E | C4: Implied PHP | D4: EV/EBITDA | E4: Implied PHP | G4: Source
A5: PayPal | B5: 7.79 | C5: =B5*$B$10 | D5: 6.12 | E5: =(D5*$B$11-Assumptions!$B$46+Assumptions!$B$41)/Assumptions!$B$45 | G5: public.com 12 Jun / valueinvesting.io 15 Jul 2026
A6: Sea | B6: 40.06 | C6: =B6*$B$10 | D6: 22.81 | E6: =(D6*$B$11-Assumptions!$B$46+Assumptions!$B$41)/Assumptions!$B$45 | G6: fullratio / public.com, Jul 2026 midpoint
A7: Grab | B7: 43 | C7: =B7*$B$10 | D7: 23.45 | E7: =(D7*$B$11-Assumptions!$B$46+Assumptions!$B$41)/Assumptions!$B$45 | G7: stockanalysis / TOPONE, 21 Jul 2026
A8: GoTo | D8: 15.1 | E8: =(D8*$B$11-Assumptions!$B$46+Assumptions!$B$41)/Assumptions!$B$45 | G8: multiples.vc, 21 Jul 2026
A10: EPS FY2025 (PHP) | B10: =Assumptions!$B$52/Assumptions!$B$45 | G10: net income / shares
A11: EBITDA FY2025 (PHP M) | B11: =Assumptions!$B$53 | G11: EV = multiple x EBITDA, then equity = EV - debt + cash, then / shares
A13: P/E, chosen statistic | B13: =IF(Assumptions!$B$60="median",MEDIAN(B5:B7),AVERAGE(B5:B7)) | C13: =B13*B10
A14: EV/EBITDA, chosen statistic | B14: =IF(Assumptions!$B$60="median",MEDIAN(D5:D8),AVERAGE(D5:D8)) | C14: =(B14*B11-Assumptions!$B$46+Assumptions!$B$41)/Assumptions!$B$45
A16: Mynt at the offer price | B16: =Assumptions!$B$44*Assumptions!$B$45/Assumptions!$B$52 | C16: =Assumptions!$B$44
A18: At the median of this peer set the P/E comparable lands ABOVE the offer price. That is the strongest form of the counter-argument, and it belongs in the open rather than behind a single undocumented multiple.

Sheet Scenarios
A1: SCENARIOS — how much of the cash balance is really free
A2: The FCFF valuation adds back a cash balance. This is what happens when you vary how much of it is genuinely distributable.
B4: 100% free | C4: 50% free | D4: 0% free | F4: Note
A5: Free-cash share | B5: 1 | C5: 0.5 | D5: 0 | F5: Matches the switch on Assumptions
A6: Free-cash adjustment (PHP M) | B6: =Assumptions!$B$38*B5 | C6: =Assumptions!$B$38*C5 | D6: =Assumptions!$B$38*D5
A7: FCFF value per share (PHP) | B7: ='DCF-FCFF'!$B$18-(Assumptions!$B$41-B6)/Assumptions!$B$45 | C7: ='DCF-FCFF'!$B$18-(Assumptions!$B$41-C6)/Assumptions!$B$45 | D7: ='DCF-FCFF'!$B$18-(Assumptions!$B$41-D6)/Assumptions!$B$45 | F7: The FCFE valuation does not add cash back, so it is unaffected.
A8: FCFE value per share (PHP) | B8: ='DCF-FCFE'!$B$15 | C8: ='DCF-FCFE'!$B$15 | D8: ='DCF-FCFE'!$B$15
A9: Offer price | B9: =Assumptions!$B$44 | C9: =Assumptions!$B$44 | D9: =Assumptions!$B$44
A11: Prospectus printed p.44 states that GCash Wallet funds are held in more liquid assets and cannot be used to facilitate lending. The only observed distribution is the PHP 5,001.2m dividend of 17 June 2026, which is 11.9% of the cash balance being added back.

Sheet Sensitivity
A1: SENSITIVITY — live grids
A2: These were 74 hardcoded cells with no formulas. Both grids now recalculate from the Assumptions tab.
A4: Beta (down) x terminal growth (across) -> FCFE PHP per share
B5: 0.03 | C5: 0.035 | D5: 0.04 | E5: 0.045 | F5: 0.05
A6: 1 | B6: ='DCF-FCFE'!$B$15*((Assumptions!$B$9-Assumptions!$B$14)/((Assumptions!$B$6+1.0*Assumptions!$B$7)-0.03)) | C6: ='DCF-FCFE'!$B$15*((Assumptions!$B$9-Assumptions!$B$14)/((Assumptions!$B$6+1.0*Assumptions!$B$7)-0.035)) | D6: ='DCF-FCFE'!$B$15*((Assumptions!$B$9-Assumptions!$B$14)/((Assumptions!$B$6+1.0*Assumptions!$B$7)-0.04)) | E6: ='DCF-FCFE'!$B$15*((Assumptions!$B$9-Assumptions!$B$14)/((Assumptions!$B$6+1.0*Assumptions!$B$7)-0.045)) | F6: ='DCF-FCFE'!$B$15*((Assumptions!$B$9-Assumptions!$B$14)/((Assumptions!$B$6+1.0*Assumptions!$B$7)-0.05))
A7: 1.2 | B7: ='DCF-FCFE'!$B$15*((Assumptions!$B$9-Assumptions!$B$14)/((Assumptions!$B$6+1.2*Assumptions!$B$7)-0.03)) | C7: ='DCF-FCFE'!$B$15*((Assumptions!$B$9-Assumptions!$B$14)/((Assumptions!$B$6+1.2*Assumptions!$B$7)-0.035)) | D7: ='DCF-FCFE'!$B$15*((Assumptions!$B$9-Assumptions!$B$14)/((Assumptions!$B$6+1.2*Assumptions!$B$7)-0.04)) | E7: ='DCF-FCFE'!$B$15*((Assumptions!$B$9-Assumptions!$B$14)/((Assumptions!$B$6+1.2*Assumptions!$B$7)-0.045)) | F7: ='DCF-FCFE'!$B$15*((Assumptions!$B$9-Assumptions!$B$14)/((Assumptions!$B$6+1.2*Assumptions!$B$7)-0.05))
A8: 1.4 | B8: ='DCF-FCFE'!$B$15*((Assumptions!$B$9-Assumptions!$B$14)/((Assumptions!$B$6+1.4*Assumptions!$B$7)-0.03)) | C8: ='DCF-FCFE'!$B$15*((Assumptions!$B$9-Assumptions!$B$14)/((Assumptions!$B$6+1.4*Assumptions!$B$7)-0.035)) | D8: ='DCF-FCFE'!$B$15*((Assumptions!$B$9-Assumptions!$B$14)/((Assumptions!$B$6+1.4*Assumptions!$B$7)-0.04)) | E8: ='DCF-FCFE'!$B$15*((Assumptions!$B$9-Assumptions!$B$14)/((Assumptions!$B$6+1.4*Assumptions!$B$7)-0.045)) | F8: ='DCF-FCFE'!$B$15*((Assumptions!$B$9-Assumptions!$B$14)/((Assumptions!$B$6+1.4*Assumptions!$B$7)-0.05))
A9: 1.6 | B9: ='DCF-FCFE'!$B$15*((Assumptions!$B$9-Assumptions!$B$14)/((Assumptions!$B$6+1.6*Assumptions!$B$7)-0.03)) | C9: ='DCF-FCFE'!$B$15*((Assumptions!$B$9-Assumptions!$B$14)/((Assumptions!$B$6+1.6*Assumptions!$B$7)-0.035)) | D9: ='DCF-FCFE'!$B$15*((Assumptions!$B$9-Assumptions!$B$14)/((Assumptions!$B$6+1.6*Assumptions!$B$7)-0.04)) | E9: ='DCF-FCFE'!$B$15*((Assumptions!$B$9-Assumptions!$B$14)/((Assumptions!$B$6+1.6*Assumptions!$B$7)-0.045)) | F9: ='DCF-FCFE'!$B$15*((Assumptions!$B$9-Assumptions!$B$14)/((Assumptions!$B$6+1.6*Assumptions!$B$7)-0.05))
A10: 1.8 | B10: ='DCF-FCFE'!$B$15*((Assumptions!$B$9-Assumptions!$B$14)/((Assumptions!$B$6+1.8*Assumptions!$B$7)-0.03)) | C10: ='DCF-FCFE'!$B$15*((Assumptions!$B$9-Assumptions!$B$14)/((Assumptions!$B$6+1.8*Assumptions!$B$7)-0.035)) | D10: ='DCF-FCFE'!$B$15*((Assumptions!$B$9-Assumptions!$B$14)/((Assumptions!$B$6+1.8*Assumptions!$B$7)-0.04)) | E10: ='DCF-FCFE'!$B$15*((Assumptions!$B$9-Assumptions!$B$14)/((Assumptions!$B$6+1.8*Assumptions!$B$7)-0.045)) | F10: ='DCF-FCFE'!$B$15*((Assumptions!$B$9-Assumptions!$B$14)/((Assumptions!$B$6+1.8*Assumptions!$B$7)-0.05))
A11: 2 | B11: ='DCF-FCFE'!$B$15*((Assumptions!$B$9-Assumptions!$B$14)/((Assumptions!$B$6+2.0*Assumptions!$B$7)-0.03)) | C11: ='DCF-FCFE'!$B$15*((Assumptions!$B$9-Assumptions!$B$14)/((Assumptions!$B$6+2.0*Assumptions!$B$7)-0.035)) | D11: ='DCF-FCFE'!$B$15*((Assumptions!$B$9-Assumptions!$B$14)/((Assumptions!$B$6+2.0*Assumptions!$B$7)-0.04)) | E11: ='DCF-FCFE'!$B$15*((Assumptions!$B$9-Assumptions!$B$14)/((Assumptions!$B$6+2.0*Assumptions!$B$7)-0.045)) | F11: ='DCF-FCFE'!$B$15*((Assumptions!$B$9-Assumptions!$B$14)/((Assumptions!$B$6+2.0*Assumptions!$B$7)-0.05))
A12: Each cell rescales the live base case by the ratio of discount spreads, so the whole grid moves when you change an assumption.
A14: Free-cash share (down) x beta (across) -> FCFF PHP per share
B15: 1 | C15: 1.2 | D15: 1.4 | E15: 1.6 | F15: 1.8
A16: 1 | B16: =('DCF-FCFF'!$B$18*((Assumptions!$B$13-Assumptions!$B$14)/((Assumptions!$B$11*Assumptions!$B$10+Assumptions!$B$12*(Assumptions!$B$6+1.0*Assumptions!$B$7))-Assumptions!$B$14)))-(Assumptions!$B$41-Assumptions!$B$38*1.0)/Assumptions!$B$45 | C16: =('DCF-FCFF'!$B$18*((Assumptions!$B$13-Assumptions!$B$14)/((Assumptions!$B$11*Assumptions!$B$10+Assumptions!$B$12*(Assumptions!$B$6+1.2*Assumptions!$B$7))-Assumptions!$B$14)))-(Assumptions!$B$41-Assumptions!$B$38*1.0)/Assumptions!$B$45 | D16: =('DCF-FCFF'!$B$18*((Assumptions!$B$13-Assumptions!$B$14)/((Assumptions!$B$11*Assumptions!$B$10+Assumptions!$B$12*(Assumptions!$B$6+1.4*Assumptions!$B$7))-Assumptions!$B$14)))-(Assumptions!$B$41-Assumptions!$B$38*1.0)/Assumptions!$B$45 | E16: =('DCF-FCFF'!$B$18*((Assumptions!$B$13-Assumptions!$B$14)/((Assumptions!$B$11*Assumptions!$B$10+Assumptions!$B$12*(Assumptions!$B$6+1.6*Assumptions!$B$7))-Assumptions!$B$14)))-(Assumptions!$B$41-Assumptions!$B$38*1.0)/Assumptions!$B$45 | F16: =('DCF-FCFF'!$B$18*((Assumptions!$B$13-Assumptions!$B$14)/((Assumptions!$B$11*Assumptions!$B$10+Assumptions!$B$12*(Assumptions!$B$6+1.8*Assumptions!$B$7))-Assumptions!$B$14)))-(Assumptions!$B$41-Assumptions!$B$38*1.0)/Assumptions!$B$45
A17: 0.75 | B17: =('DCF-FCFF'!$B$18*((Assumptions!$B$13-Assumptions!$B$14)/((Assumptions!$B$11*Assumptions!$B$10+Assumptions!$B$12*(Assumptions!$B$6+1.0*Assumptions!$B$7))-Assumptions!$B$14)))-(Assumptions!$B$41-Assumptions!$B$38*0.75)/Assumptions!$B$45 | C17: =('DCF-FCFF'!$B$18*((Assumptions!$B$13-Assumptions!$B$14)/((Assumptions!$B$11*Assumptions!$B$10+Assumptions!$B$12*(Assumptions!$B$6+1.2*Assumptions!$B$7))-Assumptions!$B$14)))-(Assumptions!$B$41-Assumptions!$B$38*0.75)/Assumptions!$B$45 | D17: =('DCF-FCFF'!$B$18*((Assumptions!$B$13-Assumptions!$B$14)/((Assumptions!$B$11*Assumptions!$B$10+Assumptions!$B$12*(Assumptions!$B$6+1.4*Assumptions!$B$7))-Assumptions!$B$14)))-(Assumptions!$B$41-Assumptions!$B$38*0.75)/Assumptions!$B$45 | E17: =('DCF-FCFF'!$B$18*((Assumptions!$B$13-Assumptions!$B$14)/((Assumptions!$B$11*Assumptions!$B$10+Assumptions!$B$12*(Assumptions!$B$6+1.6*Assumptions!$B$7))-Assumptions!$B$14)))-(Assumptions!$B$41-Assumptions!$B$38*0.75)/Assumptions!$B$45 | F17: =('DCF-FCFF'!$B$18*((Assumptions!$B$13-Assumptions!$B$14)/((Assumptions!$B$11*Assumptions!$B$10+Assumptions!$B$12*(Assumptions!$B$6+1.8*Assumptions!$B$7))-Assumptions!$B$14)))-(Assumptions!$B$41-Assumptions!$B$38*0.75)/Assumptions!$B$45
A18: 0.5 | B18: =('DCF-FCFF'!$B$18*((Assumptions!$B$13-Assumptions!$B$14)/((Assumptions!$B$11*Assumptions!$B$10+Assumptions!$B$12*(Assumptions!$B$6+1.0*Assumptions!$B$7))-Assumptions!$B$14)))-(Assumptions!$B$41-Assumptions!$B$38*0.5)/Assumptions!$B$45 | C18: =('DCF-FCFF'!$B$18*((Assumptions!$B$13-Assumptions!$B$14)/((Assumptions!$B$11*Assumptions!$B$10+Assumptions!$B$12*(Assumptions!$B$6+1.2*Assumptions!$B$7))-Assumptions!$B$14)))-(Assumptions!$B$41-Assumptions!$B$38*0.5)/Assumptions!$B$45 | D18: =('DCF-FCFF'!$B$18*((Assumptions!$B$13-Assumptions!$B$14)/((Assumptions!$B$11*Assumptions!$B$10+Assumptions!$B$12*(Assumptions!$B$6+1.4*Assumptions!$B$7))-Assumptions!$B$14)))-(Assumptions!$B$41-Assumptions!$B$38*0.5)/Assumptions!$B$45 | E18: =('DCF-FCFF'!$B$18*((Assumptions!$B$13-Assumptions!$B$14)/((Assumptions!$B$11*Assumptions!$B$10+Assumptions!$B$12*(Assumptions!$B$6+1.6*Assumptions!$B$7))-Assumptions!$B$14)))-(Assumptions!$B$41-Assumptions!$B$38*0.5)/Assumptions!$B$45 | F18: =('DCF-FCFF'!$B$18*((Assumptions!$B$13-Assumptions!$B$14)/((Assumptions!$B$11*Assumptions!$B$10+Assumptions!$B$12*(Assumptions!$B$6+1.8*Assumptions!$B$7))-Assumptions!$B$14)))-(Assumptions!$B$41-Assumptions!$B$38*0.5)/Assumptions!$B$45
A19: 0.25 | B19: =('DCF-FCFF'!$B$18*((Assumptions!$B$13-Assumptions!$B$14)/((Assumptions!$B$11*Assumptions!$B$10+Assumptions!$B$12*(Assumptions!$B$6+1.0*Assumptions!$B$7))-Assumptions!$B$14)))-(Assumptions!$B$41-Assumptions!$B$38*0.25)/Assumptions!$B$45 | C19: =('DCF-FCFF'!$B$18*((Assumptions!$B$13-Assumptions!$B$14)/((Assumptions!$B$11*Assumptions!$B$10+Assumptions!$B$12*(Assumptions!$B$6+1.2*Assumptions!$B$7))-Assumptions!$B$14)))-(Assumptions!$B$41-Assumptions!$B$38*0.25)/Assumptions!$B$45 | D19: =('DCF-FCFF'!$B$18*((Assumptions!$B$13-Assumptions!$B$14)/((Assumptions!$B$11*Assumptions!$B$10+Assumptions!$B$12*(Assumptions!$B$6+1.4*Assumptions!$B$7))-Assumptions!$B$14)))-(Assumptions!$B$41-Assumptions!$B$38*0.25)/Assumptions!$B$45 | E19: =('DCF-FCFF'!$B$18*((Assumptions!$B$13-Assumptions!$B$14)/((Assumptions!$B$11*Assumptions!$B$10+Assumptions!$B$12*(Assumptions!$B$6+1.6*Assumptions!$B$7))-Assumptions!$B$14)))-(Assumptions!$B$41-Assumptions!$B$38*0.25)/Assumptions!$B$45 | F19: =('DCF-FCFF'!$B$18*((Assumptions!$B$13-Assumptions!$B$14)/((Assumptions!$B$11*Assumptions!$B$10+Assumptions!$B$12*(Assumptions!$B$6+1.8*Assumptions!$B$7))-Assumptions!$B$14)))-(Assumptions!$B$41-Assumptions!$B$38*0.25)/Assumptions!$B$45
A20: 0 | B20: =('DCF-FCFF'!$B$18*((Assumptions!$B$13-Assumptions!$B$14)/((Assumptions!$B$11*Assumptions!$B$10+Assumptions!$B$12*(Assumptions!$B$6+1.0*Assumptions!$B$7))-Assumptions!$B$14)))-(Assumptions!$B$41-Assumptions!$B$38*0.0)/Assumptions!$B$45 | C20: =('DCF-FCFF'!$B$18*((Assumptions!$B$13-Assumptions!$B$14)/((Assumptions!$B$11*Assumptions!$B$10+Assumptions!$B$12*(Assumptions!$B$6+1.2*Assumptions!$B$7))-Assumptions!$B$14)))-(Assumptions!$B$41-Assumptions!$B$38*0.0)/Assumptions!$B$45 | D20: =('DCF-FCFF'!$B$18*((Assumptions!$B$13-Assumptions!$B$14)/((Assumptions!$B$11*Assumptions!$B$10+Assumptions!$B$12*(Assumptions!$B$6+1.4*Assumptions!$B$7))-Assumptions!$B$14)))-(Assumptions!$B$41-Assumptions!$B$38*0.0)/Assumptions!$B$45 | E20: =('DCF-FCFF'!$B$18*((Assumptions!$B$13-Assumptions!$B$14)/((Assumptions!$B$11*Assumptions!$B$10+Assumptions!$B$12*(Assumptions!$B$6+1.6*Assumptions!$B$7))-Assumptions!$B$14)))-(Assumptions!$B$41-Assumptions!$B$38*0.0)/Assumptions!$B$45 | F20: =('DCF-FCFF'!$B$18*((Assumptions!$B$13-Assumptions!$B$14)/((Assumptions!$B$11*Assumptions!$B$10+Assumptions!$B$12*(Assumptions!$B$6+1.8*Assumptions!$B$7))-Assumptions!$B$14)))-(Assumptions!$B$41-Assumptions!$B$38*0.0)/Assumptions!$B$45

Sheet Output
A1: OUTPUT — football field
A3: Method | B3: PHP per share | C3: vs offer | E3: Note
A4: DCF — FCFF (firm) | B4: ='DCF-FCFF'!$B$18 | C4: =B4/$B$12-1 | E4: discounted at WACC
A5: DCF — FCFE (equity, primary) | B5: ='DCF-FCFE'!$B$15 | C5: =B5/$B$12-1 | E5: discounted at the cost of equity
A6: Justified P/B — low | B6: ='Justified Multiples'!$B$12 | C6: =B6/$B$12-1 | E6: ending-equity ROE
A7: Justified P/B — high | B7: ='Justified Multiples'!$B$11 | C7: =B7/$B$12-1 | E7: average-equity ROE
A8: Comps — P/E, statistic | B8: =Comps!$C$13 | C8: =B8/$B$12-1 | E8: median of the peer set — lands ABOVE the offer
A9: Comps — P/E, low peer | B9: =MIN(Comps!$C$5:$C$7) | C9: =B9/$B$12-1 | E9: PayPal
A10: Comps — P/E, high peer | B10: =MAX(Comps!$C$5:$C$7) | C10: =B10/$B$12-1 | E10: Grab
A11: Comps — EV/EBITDA, statistic | B11: =Comps!$C$14 | C11: =B11/$B$12-1
A12: IPO offer price | B12: =Assumptions!$B$44
A14: VERDICT
A15: Offer as a multiple of FCFE intrinsic value | B15: =Assumptions!$B$44/'DCF-FCFE'!$B$15
A16: Methods below the offer price | B16: =COUNTIF(B4:B11,"<"&$B$12)&" of "&COUNT(B4:B11)
A18: The P/E comparable at the median of the peer set lands above the offer price. That is the strongest counter-argument to the conclusion and it is shown here rather than compressed into a single undocumented multiple.
A19: Every cash-flow method lands well below. The gap between the two is the question of whether Mynt is priced as a Philippine lender or as a global fintech.
